Workbook

Sheet Master Dashboard
A1: SmartOps | MIS Management System — Master Dashboard
A2: Executive overview • Formula-driven KPIs, operational breakdown tables, and performance charts
A4: Total Orders | D4: Delivered Orders | G4: Pending / Processing Orders | J4: Total Order Value
A5: =COUNTA(OrdersTable[Order ID]) -> 60 | D5: =COUNTIF(OrdersTable[Order Status],"Delivered") -> 34 | G5: =COUNTIF(OrdersTable[Order Status],"Pending")+COUNTIF(OrdersTable[Order Status],"Processing") -> 21 | J5: =SUM(OrdersTable[Order Value (₹)]) -> 452183
A8: Inventory Value | D8: Low-Stock Products | G8: Completed Field Activities | J8: Overdue Checklist Tasks
A9: =SUM(InventoryTable[Inventory Value (₹)]) -> 384115 | D9: =COUNTIF(InventoryTable[Reorder Alert],"REORDER") -> 4 | G9: =COUNTIF(FMSTable[Status],"Completed") -> 27 | J9: =COUNTIF(ChecklistTable[Compliance Status],"Overdue") -> 16
A13: Order Status | B13: Count | D13: Inventory Status | E13: Products | G13: Employee | H13: Completed Activities | J13: Task Compliance | K13: Count
A14: Delivered | B14: =COUNTIF(OrdersTable[Order Status],A14) -> 34 | D14: OK | E14: =COUNTIF(InventoryTable[Reorder Alert],"OK") -> 6 | G14: Aarav Sharma | H14: =COUNTIFS(FMSTable[Employee Name (XLOOKUP)],G14,FMSTable[Status],"Completed") -> 3 | J14: On Time | K14: =COUNTIF(ChecklistTable[Compliance Status],J14) -> 30
A15: Pending | B15: =COUNTIF(OrdersTable[Order Status],A15) -> 8 | D15: REORDER | E15: =COUNTIF(InventoryTable[Reorder Alert],"REORDER") -> 4 | G15: Diya Verma | H15: =COUNTIFS(FMSTable[Employee Name (XLOOKUP)],G15,FMSTable[Status],"Completed") -> 2 | J15: Delayed | K15: =COUNTIF(ChecklistTable[Compliance Status],J15) -> 14
A16: Processing | B16: =COUNTIF(OrdersTable[Order Status],A16) -> 13 | D16: Total | E16: =SUM(E14:E15) -> 10 | G16: Kabir Patel | H16: =COUNTIFS(FMSTable[Employee Name (XLOOKUP)],G16,FMSTable[Status],"Completed") -> 3 | J16: Overdue | K16: =COUNTIF(ChecklistTable[Compliance Status],J16) -> 16
A17: Cancelled | B17: =COUNTIF(OrdersTable[Order Status],A17) -> 1 | G17: Meera Singh | H17: =COUNTIFS(FMSTable[Employee Name (XLOOKUP)],G17,FMSTable[Status],"Completed") -> 2 | J17: Pending | K17: =COUNTIF(ChecklistTable[Compliance Status],J17) -> 10
A18: Returned | B18: =COUNTIF(OrdersTable[Order Status],A18) -> 4 | G18: Ishaan Gupta | H18: =COUNTIFS(FMSTable[Employee Name (XLOOKUP)],G18,FMSTable[Status],"Completed") -> 4 | J18: Total | K18: =SUM(K14:K17) -> 70
A19: Total | B19: =SUM(B14:B18) -> 60 | G19: Ananya Rao | H19: =COUNTIFS(FMSTable[Employee Name (XLOOKUP)],G19,FMSTable[Status],"Completed") -> 2
G20: Rohan Das | H20: =COUNTIFS(FMSTable[Employee Name (XLOOKUP)],G20,FMSTable[Status],"Completed") -> 3
G21: Sana Khan | H21: =COUNTIFS(FMSTable[Employee Name (XLOOKUP)],G21,FMSTable[Status],"Completed") -> 3
G22: Vivaan Joshi | H22: =COUNTIFS(FMSTable[Employee Name (XLOOKUP)],G22,FMSTable[Status],"Completed") -> 2
G23: Ira Nair | H23: =COUNTIFS(FMSTable[Employee Name (XLOOKUP)],G23,FMSTable[Status],"Completed") -> 3
G24: Total | H24: =SUM(H14:H23) -> 27

Sheet FMS Dashboard
A1: FMS Dashboard — Field Activity & Turnaround Time (TAT) Monitor
A2: Full date-time TAT subtraction (accurately handling cross-midnight activities), SLA tracking, and employee productivity
A4: Completed Activities | C4: Pending Activities | E4: In-Progress Activities | G4: Average TAT (Hours) | I4: Delayed Completed (>4h)
A5: =COUNTIF(FMSTable[Status],"Completed") -> 27 | C5: =COUNTIF(FMSTable[Status],"Pending") -> 11 | E5: =COUNTIF(FMSTable[Status],"In Progress") -> 10 | G5: =IFERROR(AVERAGE(FMSTable[TAT (Hours)]),0) -> 7.3240741 | I5: =COUNTIF(FMSTable[SLA Result],"Delayed") -> 19
A9: Employee | B9: Completed | C9: Avg TAT (hrs) | D9: Within SLA (<=4h)
A10: Aarav Sharma | B10: =COUNTIFS(FMSTable[Employee Name (XLOOKUP)],A10,FMSTable[Status],"Completed") -> 3 | C10: =IFERROR(AVERAGEIFS(FMSTable[TAT (Hours)],FMSTable[Employee Name (XLOOKUP)],A10,FMSTable[Status],"Completed"),0) -> 5 | D10: =COUNTIFS(FMSTable[Employee Name (XLOOKUP)],A10,FMSTable[SLA Result],"Within SLA") -> 1
A11: Diya Verma | B11: =COUNTIFS(FMSTable[Employee Name (XLOOKUP)],A11,FMSTable[Status],"Completed") -> 2 | C11: =IFERROR(AVERAGEIFS(FMSTable[TAT (Hours)],FMSTable[Employee Name (XLOOKUP)],A11,FMSTable[Status],"Completed"),0) -> 7.5 | D11: =COUNTIFS(FMSTable[Employee Name (XLOOKUP)],A11,FMSTable[SLA Result],"Within SLA") -> 0
A12: Kabir Patel | B12: =COUNTIFS(FMSTable[Employee Name (XLOOKUP)],A12,FMSTable[Status],"Completed") -> 3 | C12: =IFERROR(AVERAGEIFS(FMSTable[TAT (Hours)],FMSTable[Employee Name (XLOOKUP)],A12,FMSTable[Status],"Completed"),0) -> 6.4166667 | D12: =COUNTIFS(FMSTable[Employee Name (XLOOKUP)],A12,FMSTable[SLA Result],"Within SLA") -> 1
A13: Meera Singh | B13: =COUNTIFS(FMSTable[Employee Name (XLOOKUP)],A13,FMSTable[Status],"Completed") -> 2 | C13: =IFERROR(AVERAGEIFS(FMSTable[TAT (Hours)],FMSTable[Employee Name (XLOOKUP)],A13,FMSTable[Status],"Completed"),0) -> 13 | D13: =COUNTIFS(FMSTable[Employee Name (XLOOKUP)],A13,FMSTable[SLA Result],"Within SLA") -> 0
A14: Ishaan Gupta | B14: =COUNTIFS(FMSTable[Employee Name (XLOOKUP)],A14,FMSTable[Status],"Completed") -> 4 | C14: =IFERROR(AVERAGEIFS(FMSTable[TAT (Hours)],FMSTable[Employee Name (XLOOKUP)],A14,FMSTable[Status],"Completed"),0) -> 10.625 | D14: =COUNTIFS(FMSTable[Employee Name (XLOOKUP)],A14,FMSTable[SLA Result],"Within SLA") -> 1
A15: Ananya Rao | B15: =COUNTIFS(FMSTable[Employee Name (XLOOKUP)],A15,FMSTable[Status],"Completed") -> 2 | C15: =IFERROR(AVERAGEIFS(FMSTable[TAT (Hours)],FMSTable[Employee Name (XLOOKUP)],A15,FMSTable[Status],"Completed"),0) -> 3.125 | D15: =COUNTIFS(FMSTable[Employee Name (XLOOKUP)],A15,FMSTable[SLA Result],"Within SLA") -> 1
A16: Rohan Das | B16: =COUNTIFS(FMSTable[Employee Name (XLOOKUP)],A16,FMSTable[Status],"Completed") -> 3 | C16: =IFERROR(AVERAGEIFS(FMSTable[TAT (Hours)],FMSTable[Employee Name (XLOOKUP)],A16,FMSTable[Status],"Completed"),0) -> 3.5 | D16: =COUNTIFS(FMSTable[Employee Name (XLOOKUP)],A16,FMSTable[SLA Result],"Within SLA") -> 2
A17: Sana Khan | B17: =COUNTIFS(FMSTable[Employee Name (XLOOKUP)],A17,FMSTable[Status],"Completed") -> 3 | C17: =IFERROR(AVERAGEIFS(FMSTable[TAT (Hours)],FMSTable[Employee Name (XLOOKUP)],A17,FMSTable[Status],"Completed"),0) -> 11.333333 | D17: =COUNTIFS(FMSTable[Employee Name (XLOOKUP)],A17,FMSTable[SLA Result],"Within SLA") -> 0
A18: Vivaan Joshi | B18: =COUNTIFS(FMSTable[Employee Name (XLOOKUP)],A18,FMSTable[Status],"Completed") -> 2 | C18: =IFERROR(AVERAGEIFS(FMSTable[TAT (Hours)],FMSTable[Employee Name (XLOOKUP)],A18,FMSTable[Status],"Completed"),0) -> 5 | D18: =COUNTIFS(FMSTable[Employee Name (XLOOKUP)],A18,FMSTable[SLA Result],"Within SLA") -> 1
A19: Ira Nair | B19: =COUNTIFS(FMSTable[Employee Name (XLOOKUP)],A19,FMSTable[Status],"Completed") -> 3 | C19: =IFERROR(AVERAGEIFS(FMSTable[TAT (Hours)],FMSTable[Employee Name (XLOOKUP)],A19,FMSTable[Status],"Completed"),0) -> 6.4166667 | D19: =COUNTIFS(FMSTable[Employee Name (XLOOKUP)],A19,FMSTable[SLA Result],"Within SLA") -> 1
A20: Total / Overall Avg | B20: =SUM(B10:B19) -> 27 | C20: =IFERROR(AVERAGE(FMSTable[TAT (Hours)]),0) -> 7.3240741 | D20: =SUM(D10:D19) -> 8
A24: Cross-Midnight & Recent Field Activity TAT Verification Log (Live Linked to FMSTable)
A25: Activity ID | B25: Activity Date | C25: Employee ID | D25: Employee Name | E25: Activity Type | F25: Assignment Date/Time | G25: Completion Date/Time | H25: Status | I25: TAT (Hours) | J25: SLA Result
A26: ='Raw Data'!A5 -> FMS0001 | B26: ='Raw Data'!B5 -> 46311 | C26: ='Raw Data'!C5 -> E004 | D26: ='Raw Data'!D5 -> Meera Singh | E26: ='Raw Data'!E5 -> Site Visit | F26: ='Raw Data'!F5 -> 46311.365 | G26: ='Raw Data'!G5 -> 46311.906 | H26: ='Raw Data'!H5 -> Completed | ... J26: ='Raw Data'!J5 -> Delayed
A27: ='Raw Data'!A7 -> FMS0003 | B27: ='Raw Data'!B7 -> 46309 | C27: ='Raw Data'!C7 -> E010 | D27: ='Raw Data'!D7 -> Ira Nair | E27: ='Raw Data'!E7 -> Customer Follow-up | F27: ='Raw Data'!F7 -> 46309.885 | G27: ='Raw Data'!G7 -> 46309.938 | H27: ='Raw Data'!H7 -> Completed | ... J27: ='Raw Data'!J7 -> Within SLA
A28: ='Raw Data'!A8 -> FMS0004 | B28: ='Raw Data'!B8 -> 46271 | C28: ='Raw Data'!C8 -> E003 | D28: ='Raw Data'!D8 -> Kabir Patel | E28: ='Raw Data'!E8 -> Delivery Verification | F28: ='Raw Data'!F8 -> 46271.885 | G28: ='Raw Data'!G8 -> 46272.219 | H28: ='Raw Data'!H8 -> Completed | ... J28: ='Raw Data'!J8 -> Delayed
A29: ='Raw Data'!A12 -> FMS0008 | B29: ='Raw Data'!B12 -> 46306 | C29: ='Raw Data'!C12 -> E005 | D29: ='Raw Data'!D12 -> Ishaan Gupta | E29: ='Raw Data'!E12 -> Stock Audit | F29: ='Raw Data'!F12 -> 46306.771 | G29: ='Raw Data'!G12 -> 46307.312 | H29: ='Raw Data'!H12 -> Completed | ... J29: ='Raw Data'!J12 -> Delayed
A30: ='Raw Data'!A20 -> FMS0016 | B30: ='Raw Data'!B20 -> 46267 | C30: ='Raw Data'!C20 -> E009 | D30: ='Raw Data'!D20 -> Vivaan Joshi | E30: ='Raw Data'!E20 -> Delivery Verification | F30: ='Raw Data'!F20 -> 46267.677 | G30: ='Raw Data'!G20 -> 46268.01 | H30: ='Raw Data'!H20 -> Completed | ... J30: ='Raw Data'!J20 -> Delayed
A31: ='Raw Data'!A21 -> FMS0017 | B31: ='Raw Data'!B21 -> 46301 | C31: ='Raw Data'!C21 -> E002 | D31: ='Raw Data'!D21 -> Diya Verma | E31: ='Raw Data'!E21 -> Document Collection | F31: ='Raw Data'!F21 -> 46301.812 | G31: ='Raw Data'!G21 -> 46302.229 | H31: ='Raw Data'!H21 -> Completed | ... J31: ='Raw Data'!J21 -> Delayed
A32: ='Raw Data'!A22 -> FMS0018 | B32: ='Raw Data'!B22 -> 46260 | C32: ='Raw Data'!C22 -> E005 | D32: ='Raw Data'!D22 -> Ishaan Gupta | E32: ='Raw Data'!E22 -> Quality Check | F32: ='Raw Data'!F22 -> 46260.531 | G32: ='Raw Data'!G22 -> 46261.073 | H32: ='Raw Data'!H22 -> Completed | ... J32: ='Raw Data'!J22 -> Delayed
A33: ='Raw Data'!A27 -> FMS0023 | B33: ='Raw Data'!B27 -> 46310 | C33: ='Raw Data'!C27 -> E010 | D33: ='Raw Data'!D27 -> Ira Nair | E33: ='Raw Data'!E27 -> Document Collection | F33: ='Raw Data'!F27 -> 46310.927 | G33: ='Raw Data'!G27 -> 46311.469 | H33: ='Raw Data'!H27 -> Completed | ... J33: ='Raw Data'!J27 -> Delayed
A34: ='Raw Data'!A42 -> FMS0038 | B34: ='Raw Data'!B42 -> 46307 | C34: ='Raw Data'!C42 -> E005 | D34: ='Raw Data'!D42 -> Ishaan Gupta | E34: ='Raw Data'!E42 -> Stock Audit | F34: ='Raw Data'!F42 -> 46307.938 | G34: ='Raw Data'!G42 -> 46308.083 | H34: ='Raw Data'!H42 -> Completed | ... J34: ='Raw Data'!J42 -> Within SLA
A35: ='Raw Data'!A53 -> FMS0049 | B35: ='Raw Data'!B53 -> 46314 | C35: ='Raw Data'!C53 -> E008 | D35: ='Raw Data'!D53 -> Sana Khan | E35: ='Raw Data'!E53 -> Site Visit | F35: ='Raw Data'!F53 -> 46314.521 | G35: ='Raw Data'!G53 -> 46315.062 | H35: ='Raw Data'!H53 -> Completed | ... J35: ='Raw Data'!J53 -> Delayed

Sheet Checklist Dashboard
A1: Checklist Dashboard — Task Execution & On-Time Compliance
A2: Monitoring completed, pending, overdue, and delayed tasks with employee-level SLA compliance breakdown
A4: Completed Tasks | C4: Pending Tasks | E4: Overdue Tasks | G4: Delayed Tasks | I4: Task Completion Rate | K4: On-Time Compliance
A5: =COUNTIF(ChecklistTable[Task Status],"Completed") -> 44 | C5: =COUNTIF(ChecklistTable[Compliance Status],"Pending") -> 10 | E5: =COUNTIF(ChecklistTable[Compliance Status],"Overdue") -> 16 | G5: =COUNTIF(ChecklistTable[Compliance Status],"Delayed") -> 14 | I5: =IFERROR(COUNTIF(ChecklistTable[Task Status],"Completed")/COUNTA(ChecklistTable[Task ID]),0) -> 0.62857143 | K5: =IFERROR(COUNTIF(ChecklistTable[Compliance Status],"On Time")/COUNTIF(ChecklistTable[Task Status],"Completed"),0) -> 0.68181818
A8: Compliance Status Summary
A9: Compliance Status | B9: Task Count | C9: Share (%)
A10: On Time | B10: =COUNTIF(ChecklistTable[Compliance Status],A10) -> 30 | C10: =IFERROR(B10/$B$14,0) -> 0.42857143
A11: Delayed | B11: =COUNTIF(ChecklistTable[Compliance Status],A11) -> 14 | C11: =IFERROR(B11/$B$14,0) -> 0.2
A12: Overdue | B12: =COUNTIF(ChecklistTable[Compliance Status],A12) -> 16 | C12: =IFERROR(B12/$B$14,0) -> 0.22857143
A13: Pending | B13: =COUNTIF(ChecklistTable[Compliance Status],A13) -> 10 | C13: =IFERROR(B13/$B$14,0) -> 0.14285714
A14: Total | B14: =SUM(B10:B13) -> 70 | C14: =SUM(C10:C13) -> 1
A23: Employee Checklist Compliance Breakdown
A24: Employee Name | B24: Total Assigned | C24: Completed | D24: On Time | E24: Delayed | F24: Overdue | G24: On-Time Rate
A25: Aarav Sharma | B25: =COUNTIF(ChecklistTable[Employee Name (XLOOKUP)],A25) -> 7 | C25: =COUNTIFS(ChecklistTable[Employee Name (XLOOKUP)],A25,ChecklistTable[Task Status],"Completed") -> 5 | D25: =COUNTIFS(ChecklistTable[Employee Name (XLOOKUP)],A25,ChecklistTable[Compliance Status],"On Time") -> 3 | E25: =COUNTIFS(ChecklistTable[Employee Name (XLOOKUP)],A25,ChecklistTable[Compliance Status],"Delayed") -> 2 | F25: =COUNTIFS(ChecklistTable[Employee Name (XLOOKUP)],A25,ChecklistTable[Compliance Status],"Overdue") -> 2 | G25: =IFERROR(D25/C25,0) -> 0.6
A26: Diya Verma | B26: =COUNTIF(ChecklistTable[Employee Name (XLOOKUP)],A26) -> 7 | C26: =COUNTIFS(ChecklistTable[Employee Name (XLOOKUP)],A26,ChecklistTable[Task Status],"Completed") -> 5 | D26: =COUNTIFS(ChecklistTable[Employee Name (XLOOKUP)],A26,ChecklistTable[Compliance Status],"On Time") -> 2 | E26: =COUNTIFS(ChecklistTable[Employee Name (XLOOKUP)],A26,ChecklistTable[Compliance Status],"Delayed") -> 3 | F26: =COUNTIFS(ChecklistTable[Employee Name (XLOOKUP)],A26,ChecklistTable[Compliance Status],"Overdue") -> 1 | G26: =IFERROR(D26/C26,0) -> 0.4
A27: Kabir Patel | B27: =COUNTIF(ChecklistTable[Employee Name (XLOOKUP)],A27) -> 7 | C27: =COUNTIFS(ChecklistTable[Employee Name (XLOOKUP)],A27,ChecklistTable[Task Status],"Completed") -> 5 | D27: =COUNTIFS(ChecklistTable[Employee Name (XLOOKUP)],A27,ChecklistTable[Compliance Status],"On Time") -> 3 | E27: =COUNTIFS(ChecklistTable[Employee Name (XLOOKUP)],A27,ChecklistTable[Compliance Status],"Delayed") -> 2 | F27: =COUNTIFS(ChecklistTable[Employee Name (XLOOKUP)],A27,ChecklistTable[Compliance Status],"Overdue") -> 1 | G27: =IFERROR(D27/C27,0) -> 0.6
A28: Meera Singh | B28: =COUNTIF(ChecklistTable[Employee Name (XLOOKUP)],A28) -> 7 | C28: =COUNTIFS(ChecklistTable[Employee Name (XLOOKUP)],A28,ChecklistTable[Task Status],"Completed") -> 3 | D28: =COUNTIFS(ChecklistTable[Employee Name (XLOOKUP)],A28,ChecklistTable[Compliance Status],"On Time") -> 3 | E28: =COUNTIFS(ChecklistTable[Employee Name (XLOOKUP)],A28,ChecklistTable[Compliance Status],"Delayed") -> 0 | F28: =COUNTIFS(ChecklistTable[Employee Name (XLOOKUP)],A28,ChecklistTable[Compliance Status],"Overdue") -> 3 | G28: =IFERROR(D28/C28,0) -> 1
A29: Ishaan Gupta | B29: =COUNTIF(ChecklistTable[Employee Name (XLOOKUP)],A29) -> 7 | C29: =COUNTIFS(ChecklistTable[Employee Name (XLOOKUP)],A29,ChecklistTable[Task Status],"Completed") -> 6 | D29: =COUNTIFS(ChecklistTable[Employee Name (XLOOKUP)],A29,ChecklistTable[Compliance Status],"On Time") -> 3 | E29: =COUNTIFS(ChecklistTable[Employee Name (XLOOKUP)],A29,ChecklistTable[Compliance Status],"Delayed") -> 3 | F29: =COUNTIFS(ChecklistTable[Employee Name (XLOOKUP)],A29,ChecklistTable[Compliance Status],"Overdue") -> 1 | G29: =IFERROR(D29/C29,0) -> 0.5
A30: Ananya Rao | B30: =COUNTIF(ChecklistTable[Employee Name (XLOOKUP)],A30) -> 7 | C30: =COUNTIFS(ChecklistTable[Employee Name (XLOOKUP)],A30,ChecklistTable[Task Status],"Completed") -> 5 | D30: =COUNTIFS(ChecklistTable[Employee Name (XLOOKUP)],A30,ChecklistTable[Compliance Status],"On Time") -> 4 | E30: =COUNTIFS(ChecklistTable[Employee Name (XLOOKUP)],A30,ChecklistTable[Compliance Status],"Delayed") -> 1 | F30: =COUNTIFS(ChecklistTable[Employee Name (XLOOKUP)],A30,ChecklistTable[Compliance Status],"Overdue") -> 1 | G30: =IFERROR(D30/C30,0) -> 0.8
A31: Rohan Das | B31: =COUNTIF(ChecklistTable[Employee Name (XLOOKUP)],A31) -> 7 | C31: =COUNTIFS(ChecklistTable[Employee Name (XLOOKUP)],A31,ChecklistTable[Task Status],"Completed") -> 6 | D31: =COUNTIFS(ChecklistTable[Employee Name (XLOOKUP)],A31,ChecklistTable[Compliance Status],"On Time") -> 5 | E31: =COUNTIFS(ChecklistTable[Employee Name (XLOOKUP)],A31,ChecklistTable[Compliance Status],"Delayed") -> 1 | F31: =COUNTIFS(ChecklistTable[Employee Name (XLOOKUP)],A31,ChecklistTable[Compliance Status],"Overdue") -> 1 | G31: =IFERROR(D31/C31,0) -> 0.83333333
A32: Sana Khan | B32: =COUNTIF(ChecklistTable[Employee Name (XLOOKUP)],A32) -> 7 | C32: =COUNTIFS(ChecklistTable[Employee Name (XLOOKUP)],A32,ChecklistTable[Task Status],"Completed") -> 2 | D32: =COUNTIFS(ChecklistTable[Employee Name (XLOOKUP)],A32,ChecklistTable[Compliance Status],"On Time") -> 1 | E32: =COUNTIFS(ChecklistTable[Employee Name (XLOOKUP)],A32,ChecklistTable[Compliance Status],"Delayed") -> 1 | F32: =COUNTIFS(ChecklistTable[Employee Name (XLOOKUP)],A32,ChecklistTable[Compliance Status],"Overdue") -> 4 | G32: =IFERROR(D32/C32,0) -> 0.5
A33: Vivaan Joshi | B33: =COUNTIF(ChecklistTable[Employee Name (XLOOKUP)],A33) -> 7 | C33: =COUNTIFS(ChecklistTable[Employee Name (XLOOKUP)],A33,ChecklistTable[Task Status],"Completed") -> 3 | D33: =COUNTIFS(ChecklistTable[Employee Name (XLOOKUP)],A33,ChecklistTable[Compliance Status],"On Time") -> 3 | E33: =COUNTIFS(ChecklistTable[Employee Name (XLOOKUP)],A33,ChecklistTable[Compliance Status],"Delayed") -> 0 | F33: =COUNTIFS(ChecklistTable[Employee Name (XLOOKUP)],A33,ChecklistTable[Compliance Status],"Overdue") -> 2 | G33: =IFERROR(D33/C33,0) -> 1
A34: Ira Nair | B34: =COUNTIF(ChecklistTable[Employee Name (XLOOKUP)],A34) -> 7 | C34: =COUNTIFS(ChecklistTable[Employee Name (XLOOKUP)],A34,ChecklistTable[Task Status],"Completed") -> 4 | D34: =COUNTIFS(ChecklistTable[Employee Name (XLOOKUP)],A34,ChecklistTable[Compliance Status],"On Time") -> 3 | E34: =COUNTIFS(ChecklistTable[Employee Name (XLOOKUP)],A34,ChecklistTable[Compliance Status],"Delayed") -> 1 | F34: =COUNTIFS(ChecklistTable[Employee Name (XLOOKUP)],A34,ChecklistTable[Compliance Status],"Overdue") -> 0 | G34: =IFERROR(D34/C34,0) -> 0.75
A35: Total / Overall | B35: =SUM(B25:B34) -> 70 | C35: =SUM(C25:C34) -> 44 | D35: =SUM(D25:D34) -> 30 | E35: =SUM(E25:E34) -> 14 | F35: =SUM(F25:F34) -> 16 | G35: =IFERROR(D35/C35,0) -> 0.68181818

Sheet Order Tracking
A1: Order Tracking
A2: Order lifecycle register with XLOOKUP employee details, status dropdowns, overdue flags, and quality checks
A3: Order ID | B3: Order Date | C3: Customer | D3: Product ID | E3: Product | F3: Quantity | G3: Unit Price (₹) | H3: Order Value (₹) | I3: Employee ID | J3: Employee Name (XLOOKUP) | K3: Order Status | L3: Expected Delivery | M3: Actual Delivery | N3: Overdue Status | P3: Order Audit & Summary | Q3: Status / Count
A4: ORD0001 | B4: 46310 | C4: Northstar Services | D4: P001 | E4: Wireless Mouse | F4: 2 | G4: 499 | H4: =F4*G4 -> 998 | I4: E001 | J4: =IFERROR(_xlfn.XLOOKUP(I4,EmployeeTable[Employee ID],EmployeeTable[Employee Name],"Not found"),IFERROR(INDEX(EmployeeTable[Employee Name],MATCH(I4,EmployeeTable[Employee ID],0)),"Not found")) -> Aarav Sharma | K4: Processing | L4: 46316 | N4: =IF(AND(OR(K4="Pending",K4="Processing"),L4<TODAY()),"Overdue","On Track") -> On Track | P4: Duplicate Order IDs | Q4: =IF(SUMPRODUCT(--(COUNTIF(OrdersTable[Order ID],OrdersTable[Order ID])>1))>0,"DUPLICATES FOUND","IDs unique") -> IDs unique
A5: ORD0002 | B5: 46311 | C5: BluePeak Retail | D5: P002 | E5: Keyboard | F5: 4 | G5: 899 | H5: =F5*G5 -> 3596 | I5: E002 | J5: =IFERROR(_xlfn.XLOOKUP(I5,EmployeeTable[Employee ID],EmployeeTable[Employee Name],"Not found"),IFERROR(INDEX(EmployeeTable[Employee Name],MATCH(I5,EmployeeTable[Employee ID],0)),"Not found")) -> Diya Verma | K5: Processing | L5: 46317 | N5: =IF(AND(OR(K5="Pending",K5="Processing"),L5<TODAY()),"Overdue","On Track") -> On Track | P5: Missing Customer/Product | Q5: =IF(COUNTBLANK(OrdersTable[Customer])+COUNTBLANK(OrdersTable[Product ID])>0,"MISSING VALUES","Complete") -> Complete
A6: ORD0003 | B6: 46228 | C6: Cedar & Co. | D6: P003 | E6: USB-C Hub | F6: 12 | G6: 1499 | H6: =F6*G6 -> 17988 | I6: E003 | J6: =IFERROR(_xlfn.XLOOKUP(I6,EmployeeTable[Employee ID],EmployeeTable[Employee Name],"Not found"),IFERROR(INDEX(EmployeeTable[Employee Name],MATCH(I6,EmployeeTable[Employee ID],0)),"Not found")) -> Kabir Patel | K6: Delivered | L6: 46238 | M6: 46238 | N6: =IF(AND(OR(K6="Pending",K6="Processing"),L6<TODAY()),"Overdue","On Track") -> On Track | P6: Total Orders | Q6: =COUNTA(OrdersTable[Order ID]) -> 60
A7: ORD0004 | B7: 46310 | C7: Summit Logistics | D7: P004 | E7: Laptop Stand | F7: 1 | G7: 1199 | H7: =F7*G7 -> 1199 | I7: E004 | J7: =IFERROR(_xlfn.XLOOKUP(I7,EmployeeTable[Employee ID],EmployeeTable[Employee Name],"Not found"),IFERROR(INDEX(EmployeeTable[Employee Name],MATCH(I7,EmployeeTable[Employee ID],0)),"Not found")) -> Meera Singh | K7: Delivered | L7: 46313 | M7: 46314 | N7: =IF(AND(OR(K7="Pending",K7="Processing"),L7<TODAY()),"Overdue","On Track") -> On Track | P7: Delivered Orders | Q7: =COUNTIF(OrdersTable[Order Status],"Delivered") -> 34
A8: ORD0005 | B8: 46237 | C8: Orbit Systems | D8: P005 | E8: Webcam HD | F8: 1 | G8: 2499 | H8: =F8*G8 -> 2499 | I8: E005 | J8: =IFERROR(_xlfn.XLOOKUP(I8,EmployeeTable[Employee ID],EmployeeTable[Employee Name],"Not found"),IFERROR(INDEX(EmployeeTable[Employee Name],MATCH(I8,EmployeeTable[Employee ID],0)),"Not found")) -> Ishaan Gupta | K8: Delivered | L8: 46247 | M8: 46249 | N8: =IF(AND(OR(K8="Pending",K8="Processing"),L8<TODAY()),"Overdue","On Track") -> On Track | P8: Open (Pending/Proc.) | Q8: =COUNTIF(OrdersTable[Order Status],"Pending")+COUNTIF(OrdersTable[Order Status],"Processing") -> 21
A9: ORD0006 | B9: 46225 | C9: MapleWorks | D9: P006 | E9: Headset | F9: 9 | G9: 1799 | H9: =F9*G9 -> 16191 | I9: E006 | J9: =IFERROR(_xlfn.XLOOKUP(I9,EmployeeTable[Employee ID],EmployeeTable[Employee Name],"Not found"),IFERROR(INDEX(EmployeeTable[Employee Name],MATCH(I9,EmployeeTable[Employee ID],0)),"Not found")) -> Ananya Rao | K9: Delivered | L9: 46233 | M9: 46234 | N9: =IF(AND(OR(K9="Pending",K9="Processing"),L9<TODAY()),"Overdue","On Track") -> On Track | P9: Overdue Open Orders | Q9: =COUNTIF(OrdersTable[Overdue Status],"Overdue") -> 13
A10: ORD0007 | B10: 46279 | C10: BrightPath Consulting | D10: P007 | E10: Power Adapter | F10: 1 | G10: 999 | H10: =F10*G10 -> 999 | I10: E007 | J10: =IFERROR(_xlfn.XLOOKUP(I10,EmployeeTable[Employee ID],EmployeeTable[Employee Name],"Not found"),IFERROR(INDEX(EmployeeTable[Employee Name],MATCH(I10,EmployeeTable[Employee ID],0)),"Not found")) -> Rohan Das | K10: Processing | L10: 46283 | N10: =IF(AND(OR(K10="Pending",K10="Processing"),L10<TODAY()),"Overdue","On Track") -> Overdue | P10: Returned / Cancelled | Q10: =COUNTIF(OrdersTable[Order Status],"Returned")+COUNTIF(OrdersTable[Order Status],"Cancelled") -> 5
A11: ORD0008 | B11: 46271 | C11: UrbanCart | D11: P008 | E11: Notebook Pack | F11: 5 | G11: 249 | H11: =F11*G11 -> 1245 | I11: E008 | J11: =IFERROR(_xlfn.XLOOKUP(I11,EmployeeTable[Employee ID],EmployeeTable[Employee Name],"Not found"),IFERROR(INDEX(EmployeeTable[Employee Name],MATCH(I11,EmployeeTable[Employee ID],0)),"Not found")) -> Sana Khan | K11: Delivered | L11: 46275 | M11: 46275 | N11: =IF(AND(OR(K11="Pending",K11="Processing"),L11<TODAY()),"Overdue","On Track") -> On Track | P11: Total Order Value | Q11: =SUM(OrdersTable[Order Value (₹)]) -> 452183
A12: ORD0009 | B12: 46301 | C12: Silverline Traders | D12: P009 | E12: Ethernet Cable | F12: 2 | G12: 199 | H12: =F12*G12 -> 398 | I12: E009 | J12: =IFERROR(_xlfn.XLOOKUP(I12,EmployeeTable[Employee ID],EmployeeTable[Employee Name],"Not found"),IFERROR(INDEX(EmployeeTable[Employee Name],MATCH(I12,EmployeeTable[Employee ID],0)),"Not found")) -> Vivaan Joshi | K12: Delivered | L12: 46309 | M12: 46309 | N12: =IF(AND(OR(K12="Pending",K12="Processing"),L12<TODAY()),"Overdue","On Track") -> On Track
A13: ORD0010 | B13: 46237 | C13: Nova Office Solutions | D13: P010 | E13: Portable SSD | F13: 5 | G13: 4999 | H13: =F13*G13 -> 24995 | I13: E010 | J13: =IFERROR(_xlfn.XLOOKUP(I13,EmployeeTable[Employee ID],EmployeeTable[Employee Name],"Not found"),IFERROR(INDEX(EmployeeTable[Employee Name],MATCH(I13,EmployeeTable[Employee ID],0)),"Not found")) -> Ira Nair | K13: Processing | L13: 46239 | N13: =IF(AND(OR(K13="Pending",K13="Processing"),L13<TODAY()),"Overdue","On Track") -> Overdue
A14: ORD0011 | B14: 46246 | C14: Greenfield Labs | D14: P001 | E14: Wireless Mouse | F14: 2 | G14: 499 | H14: =F14*G14 -> 998 | I14: E001 | J14: =IFERROR(_xlfn.XLOOKUP(I14,EmployeeTable[Employee ID],EmployeeTable[Employee Name],"Not found"),IFERROR(INDEX(EmployeeTable[Employee Name],MATCH(I14,EmployeeTable[Employee ID],0)),"Not found")) -> Aarav Sharma | K14: Delivered | L14: 46254 | M14: 46254 | N14: =IF(AND(OR(K14="Pending",K14="Processing"),L14<TODAY()),"Overdue","On Track") -> On Track
A15: ORD0012 | B15: 46234 | C15: Pioneer Supplies | D15: P002 | E15: Keyboard | F15: 10 | G15: 899 | H15: =F15*G15 -> 8990 | I15: E002 | J15: =IFERROR(_xlfn.XLOOKUP(I15,EmployeeTable[Employee ID],EmployeeTable[Employee Name],"Not found"),IFERROR(INDEX(EmployeeTable[Employee Name],MATCH(I15,EmployeeTable[Employee ID],0)),"Not found")) -> Diya Verma | K15: Pending | L15: 46241 | N15: =IF(AND(OR(K15="Pending",K15="Processing"),L15<TODAY()),"Overdue","On Track") -> Overdue
A16: ORD0013 | B16: 46311 | C16: Northstar Services | D16: P003 | E16: USB-C Hub | F16: 1 | G16: 1499 | H16: =F16*G16 -> 1499 | I16: E003 | J16: =IFERROR(_xlfn.XLOOKUP(I16,EmployeeTable[Employee ID],EmployeeTable[Employee Name],"Not found"),IFERROR(INDEX(EmployeeTable[Employee Name],MATCH(I16,EmployeeTable[Employee ID],0)),"Not found")) -> Kabir Patel | K16: Processing | L16: 46318 | N16: =IF(AND(OR(K16="Pending",K16="Processing"),L16<TODAY()),"Overdue","On Track") -> On Track
A17: ORD0014 | B17: 46304 | C17: BluePeak Retail | D17: P004 | E17: Laptop Stand | F17: 4 | G17: 1199 | H17: =F17*G17 -> 4796 | I17: E004 | J17: =IFERROR(_xlfn.XLOOKUP(I17,EmployeeTable[Employee ID],EmployeeTable[Employee Name],"Not found"),IFERROR(INDEX(EmployeeTable[Employee Name],MATCH(I17,EmployeeTable[Employee ID],0)),"Not found")) -> Meera Singh | K17: Delivered | L17: 46307 | M17: 46307 | N17: =IF(AND(OR(K17="Pending",K17="Processing"),L17<TODAY()),"Overdue","On Track") -> On Track
A18: ORD0015 | B18: 46233 | C18: Cedar & Co. | D18: P005 | E18: Webcam HD | F18: 6 | G18: 2499 | H18: =F18*G18 -> 14994 | I18: E005 | J18: =IFERROR(_xlfn.XLOOKUP(I18,EmployeeTable[Employee ID],EmployeeTable[Employee Name],"Not found"),IFERROR(INDEX(EmployeeTable[Employee Name],MATCH(I18,EmployeeTable[Employee ID],0)),"Not found")) -> Ishaan Gupta | K18: Delivered | L18: 46237 | M18: 46236 | N18: =IF(AND(OR(K18="Pending",K18="Processing"),L18<TODAY()),"Overdue","On Track") -> On Track
A19: ORD0016 | B19: 46229 | C19: Summit Logistics | D19: P006 | E19: Headset | F19: 5 | G19: 1799 | H19: =F19*G19 -> 8995 | I19: E006 | J19: =IFERROR(_xlfn.XLOOKUP(I19,EmployeeTable[Employee ID],EmployeeTable[Employee Name],"Not found"),IFERROR(INDEX(EmployeeTable[Employee Name],MATCH(I19,EmployeeTable[Employee ID],0)),"Not found")) -> Ananya Rao | K19: Pending | L19: 46232 | N19: =IF(AND(OR(K19="Pending",K19="Processing"),L19<TODAY()),"Overdue","On Track") -> Overdue
A20: ORD0017 | B20: 46293 | C20: Orbit Systems | D20: P007 | E20: Power Adapter | F20: 9 | G20: 999 | H20: =F20*G20 -> 8991 | I20: E007 | J20: =IFERROR(_xlfn.XLOOKUP(I20,EmployeeTable[Employee ID],EmployeeTable[Employee Name],"Not found"),IFERROR(INDEX(EmployeeTable[Employee Name],MATCH(I20,EmployeeTable[Employee ID],0)),"Not found")) -> Rohan Das | K20: Delivered | L20: 46298 | M20: 46298 | N20: =IF(AND(OR(K20="Pending",K20="Processing"),L20<TODAY()),"Overdue","On Track") -> On Track
A21: ORD0018 | B21: 46280 | C21: MapleWorks | D21: P008 | E21: Notebook Pack | F21: 11 | G21: 249 | H21: =F21*G21 -> 2739 | I21: E008 | J21: =IFERROR(_xlfn.XLOOKUP(I21,EmployeeTable[Employee ID],EmployeeTable[Employee Name],"Not found"),IFERROR(INDEX(EmployeeTable[Employee Name],MATCH(I21,EmployeeTable[Employee ID],0)),"Not found")) -> Sana Khan | K21: Delivered | L21: 46290 | M21: 46290 | N21: =IF(AND(OR(K21="Pending",K21="Processing"),L21<TODAY()),"Overdue","On Track") -> On Track
A22: ORD0019 | B22: 46309 | C22: BrightPath Consulting | D22: P009 | E22: Ethernet Cable | F22: 4 | G22: 199 | H22: =F22*G22 -> 796 | I22: E009 | J22: =IFERROR(_xlfn.XLOOKUP(I22,EmployeeTable[Employee ID],EmployeeTable[Employee Name],"Not found"),IFERROR(INDEX(EmployeeTable[Employee Name],MATCH(I22,EmployeeTable[Employee ID],0)),"Not found")) -> Vivaan Joshi | K22: Processing | L22: 46315 | N22: =IF(AND(OR(K22="Pending",K22="Processing"),L22<TODAY()),"Overdue","On Track") -> On Track
A23: ORD0020 | B23: 46263 | C23: UrbanCart | D23: P010 | E23: Portable SSD | F23: 5 | G23: 4999 | H23: =F23*G23 -> 24995 | I23: E010 | J23: =IFERROR(_xlfn.XLOOKUP(I23,EmployeeTable[Employee ID],EmployeeTable[Employee Name],"Not found"),IFERROR(INDEX(EmployeeTable[Employee Name],MATCH(I23,EmployeeTable[Employee ID],0)),"Not found")) -> Ira Nair | K23: Delivered | L23: 46266 | M23: 46267 | N23: =IF(AND(OR(K23="Pending",K23="Processing"),L23<TODAY()),"Overdue","On Track") -> On Track
A24: ORD0021 | B24: 46274 | C24: Silverline Traders | D24: P001 | E24: Wireless Mouse | F24: 4 | G24: 499 | H24: =F24*G24 -> 1996 | I24: E001 | J24: =IFERROR(_xlfn.XLOOKUP(I24,EmployeeTable[Employee ID],EmployeeTable[Employee Name],"Not found"),IFERROR(INDEX(EmployeeTable[Employee Name],MATCH(I24,EmployeeTable[Employee ID],0)),"Not found")) -> Aarav Sharma | K24: Delivered | L24: 46283 | M24: 46285 | N24: =IF(AND(OR(K24="Pending",K24="Processing"),L24<TODAY()),"Overdue","On Track") -> On Track
A25: ORD0022 | B25: 46256 | C25: Nova Office Solutions | D25: P002 | E25: Keyboard | F25: 3 | G25: 899 | H25: =F25*G25 -> 2697 | I25: E002 | J25: =IFERROR(_xlfn.XLOOKUP(I25,EmployeeTable[Employee ID],EmployeeTable[Employee Name],"Not found"),IFERROR(INDEX(EmployeeTable[Employee Name],MATCH(I25,EmployeeTable[Employee ID],0)),"Not found")) -> Diya Verma | K25: Delivered | L25: 46262 | M25: 46264 | N25: =IF(AND(OR(K25="Pending",K25="Processing"),L25<TODAY()),"Overdue","On Track") -> On Track
A26: ORD0023 | B26: 46243 | C26: Greenfield Labs | D26: P003 | E26: USB-C Hub | F26: 9 | G26: 1499 | H26: =F26*G26 -> 13491 | I26: E003 | J26: =IFERROR(_xlfn.XLOOKUP(I26,EmployeeTable[Employee ID],EmployeeTable[Employee Name],"Not found"),IFERROR(INDEX(EmployeeTable[Employee Name],MATCH(I26,EmployeeTable[Employee ID],0)),"Not found")) -> Kabir Patel | K26: Processing | L26: 46249 | N26: =IF(AND(OR(K26="Pending",K26="Processing"),L26<TODAY()),"Overdue","On Track") -> Overdue
A27: ORD0024 | B27: 46260 | C27: Pioneer Supplies | D27: P004 | E27: Laptop Stand | F27: 10 | G27: 1199 | H27: =F27*G27 -> 11990 | I27: E004 | J27: =IFERROR(_xlfn.XLOOKUP(I27,EmployeeTable[Employee ID],EmployeeTable[Employee Name],"Not found"),IFERROR(INDEX(EmployeeTable[Employee Name],MATCH(I27,EmployeeTable[Employee ID],0)),"Not found")) -> Meera Singh | K27: Delivered | L27: 46268 | M27: 46267 | N27: =IF(AND(OR(K27="Pending",K27="Processing"),L27<TODAY()),"Overdue","On Track") -> On Track
A28: ORD0025 | B28: 46249 | C28: Northstar Services | D28: P005 | E28: Webcam HD | F28: 8 | G28: 2499 | H28: =F28*G28 -> 19992 | I28: E005 | J28: =IFERROR(_xlfn.XLOOKUP(I28,EmployeeTable[Employee ID],EmployeeTable[Employee Name],"Not found"),IFERROR(INDEX(EmployeeTable[Employee Name],MATCH(I28,EmployeeTable[Employee ID],0)),"Not found")) -> Ishaan Gupta | K28: Processing | L28: 46252 | N28: =IF(AND(OR(K28="Pending",K28="Processing"),L28<TODAY()),"Overdue","On Track") -> Overdue
A29: ORD0026 | B29: 46312 | C29: BluePeak Retail | D29: P006 | E29: Headset | F29: 3 | G29: 1799 | H29: =F29*G29 -> 5397 | I29: E006 | J29: =IFERROR(_xlfn.XLOOKUP(I29,EmployeeTable[Employee ID],EmployeeTable[Employee Name],"Not found"),IFERROR(INDEX(EmployeeTable[Employee Name],MATCH(I29,EmployeeTable[Employee ID],0)),"Not found")) -> Ananya Rao | K29: Processing | L29: 46319 | N29: =IF(AND(OR(K29="Pending",K29="Processing"),L29<TODAY()),"Overdue","On Track") -> On Track
A30: ORD0027 | B30: 46260 | C30: Cedar & Co. | D30: P007 | E30: Power Adapter | F30: 10 | G30: 999 | H30: =F30*G30 -> 9990 | I30: E007 | J30: =IFERROR(_xlfn.XLOOKUP(I30,EmployeeTable[Employee ID],EmployeeTable[Employee Name],"Not found"),IFERROR(INDEX(EmployeeTable[Employee Name],MATCH(I30,EmployeeTable[Employee ID],0)),"Not found")) -> Rohan Das | K30: Delivered | L30: 46263 | M30: 46264 | N30: =IF(AND(OR(K30="Pending",K30="Processing"),L30<TODAY()),"Overdue","On Track") -> On Track
A31: ORD0028 | B31: 46255 | C31: Summit Logistics | D31: P008 | E31: Notebook Pack | F31: 9 | G31: 249 | H31: =F31*G31 -> 2241 | I31: E008 | J31: =IFERROR(_xlfn.XLOOKUP(I31,EmployeeTable[Employee ID],EmployeeTable[Employee Name],"Not found"),IFERROR(INDEX(EmployeeTable[Employee Name],MATCH(I31,EmployeeTable[Employee ID],0)),"Not found")) -> Sana Khan | K31: Returned | L31: 46261 | M31: 46260 | N31: =IF(AND(OR(K31="Pending",K31="Processing"),L31<TODAY()),"Overdue","On Track") -> On Track
A32: ORD0029 | B32: 46227 | C32: Orbit Systems | D32: P009 | E32: Ethernet Cable | F32: 12 | G32: 199 | H32: =F32*G32 -> 2388 | I32: E009 | J32: =IFERROR(_xlfn.XLOOKUP(I32,EmployeeTable[Employee ID],EmployeeTable[Employee Name],"Not found"),IFERROR(INDEX(EmployeeTable[Employee Name],MATCH(I32,EmployeeTable[Employee ID],0)),"Not found")) -> Vivaan Joshi | K32: Processing | L32: 46230 | N32: =IF(AND(OR(K32="Pending",K32="Processing"),L32<TODAY()),"Overdue","On Track") -> Overdue
A33: ORD0030 | B33: 46246 | C33: MapleWorks | D33: P010 | E33: Portable SSD | F33: 5 | G33: 4999 | H33: =F33*G33 -> 24995 | I33: E010 | J33: =IFERROR(_xlfn.XLOOKUP(I33,EmployeeTable[Employee ID],EmployeeTable[Employee Name],"Not found"),IFERROR(INDEX(EmployeeTable[Employee Name],MATCH(I33,EmployeeTable[Employee ID],0)),"Not found")) -> Ira Nair | K33: Delivered | L33: 46253 | M33: 46253 | N33: =IF(AND(OR(K33="Pending",K33="Processing"),L33<TODAY()),"Overdue","On Track") -> On Track
A34: ORD0031 | B34: 46294 | C34: BrightPath Consulting | D34: P001 | E34: Wireless Mouse | F34: 8 | G34: 499 | H34: =F34*G34 -> 3992 | I34: E001 | J34: =IFERROR(_xlfn.XLOOKUP(I34,EmployeeTable[Employee ID],EmployeeTable[Employee Name],"Not found"),IFERROR(INDEX(EmployeeTable[Employee Name],MATCH(I34,EmployeeTable[Employee ID],0)),"Not found")) -> Aarav Sharma | K34: Returned | L34: 46296 | M34: 46297 | N34: =IF(AND(OR(K34="Pending",K34="Processing"),L34<TODAY()),"Overdue","On Track") -> On Track
A35: ORD0032 | B35: 46250 | C35: UrbanCart | D35: P002 | E35: Keyboard | F35: 3 | G35: 899 | H35: =F35*G35 -> 2697 | I35: E002 | J35: =IFERROR(_xlfn.XLOOKUP(I35,EmployeeTable[Employee ID],EmployeeTable[Employee Name],"Not found"),IFERROR(INDEX(EmployeeTable[Employee Name],MATCH(I35,EmployeeTable[Employee ID],0)),"Not found")) -> Diya Verma | K35: Cancelled | L35: 46260 | N35: =IF(AND(OR(K35="Pending",K35="Processing"),L35<TODAY()),"Overdue","On Track") -> On Track
A36: ORD0033 | B36: 46234 | C36: Silverline Traders | D36: P003 | E36: USB-C Hub | F36: 5 | G36: 1499 | H36: =F36*G36 -> 7495 | I36: E003 | J36: =IFERROR(_xlfn.XLOOKUP(I36,EmployeeTable[Employee ID],EmployeeTable[Employee Name],"Not found"),IFERROR(INDEX(EmployeeTable[Employee Name],MATCH(I36,EmployeeTable[Employee ID],0)),"Not found")) -> Kabir Patel | K36: Pending | L36: 46244 | N36: =IF(AND(OR(K36="Pending",K36="Processing"),L36<TODAY()),"Overdue","On Track") -> Overdue
A37: ORD0034 | B37: 46310 | C37: Nova Office Solutions | D37: P004 | E37: Laptop Stand | F37: 6 | G37: 1199 | H37: =F37*G37 -> 7194 | I37: E004 | J37: =IFERROR(_xlfn.XLOOKUP(I37,EmployeeTable[Employee ID],EmployeeTable[Employee Name],"Not found"),IFERROR(INDEX(EmployeeTable[Employee Name],MATCH(I37,EmployeeTable[Employee ID],0)),"Not found")) -> Meera Singh | K37: Pending | L37: 46317 | N37: =IF(AND(OR(K37="Pending",K37="Processing"),L37<TODAY()),"Overdue","On Track") -> On Track
A38: ORD0035 | B38: 46247 | C38: Greenfield Labs | D38: P005 | E38: Webcam HD | F38: 1 | G38: 2499 | H38: =F38*G38 -> 2499 | I38: E005 | J38: =IFERROR(_xlfn.XLOOKUP(I38,EmployeeTable[Employee ID],EmployeeTable[Employee Name],"Not found"),IFERROR(INDEX(EmployeeTable[Employee Name],MATCH(I38,EmployeeTable[Employee ID],0)),"Not found")) -> Ishaan Gupta | K38: Pending | L38: 46254 | N38: =IF(AND(OR(K38="Pending",K38="Processing"),L38<TODAY()),"Overdue","On Track") -> Overdue
A39: ORD0036 | B39: 46300 | C39: Pioneer Supplies | D39: P006 | E39: Headset | F39: 6 | G39: 1799 | H39: =F39*G39 -> 10794 | I39: E006 | J39: =IFERROR(_xlfn.XLOOKUP(I39,EmployeeTable[Employee ID],EmployeeTable[Employee Name],"Not found"),IFERROR(INDEX(EmployeeTable[Employee Name],MATCH(I39,EmployeeTable[Employee ID],0)),"Not found")) -> Ananya Rao | K39: Delivered | L39: 46306 | M39: 46305 | N39: =IF(AND(OR(K39="Pending",K39="Processing"),L39<TODAY()),"Overdue","On Track") -> On Track
A40: ORD0037 | B40: 46313 | C40: Northstar Services | D40: P007 | E40: Power Adapter | F40: 2 | G40: 999 | H40: =F40*G40 -> 1998 | I40: E007 | J40: =IFERROR(_xlfn.XLOOKUP(I40,EmployeeTable[Employee ID],EmployeeTable[Employee Name],"Not found"),IFERROR(INDEX(EmployeeTable[Employee Name],MATCH(I40,EmployeeTable[Employee ID],0)),"Not found")) -> Rohan Das | K40: Processing | L40: 46320 | N40: =IF(AND(OR(K40="Pending",K40="Processing"),L40<TODAY()),"Overdue","On Track") -> On Track
...

Sheet Inventory Management
A1: Inventory Management
A2: Automated stock balances, Indian Rupee (₹) valuation, reorder threshold alerts, and stock level visualization
A3: Product ID | B3: Product Name | C3: Category | D3: Opening Stock | E3: Stock Received | F3: Stock Issued | G3: Current Stock | H3: Reorder Level | I3: Unit Cost (₹) | J3: Inventory Value (₹) | K3: Reorder Alert | M3: Data Quality & Summary | N3: Status / Value
A4: P001 | B4: Wireless Mouse | C4: Accessories | D4: 120 | E4: 24 | F4: 25 | G4: =D4 + E4 - F4 -> 119 | H4: 35 | I4: 499 | J4: =MAX(G4,0)*I4 -> 59381 | K4: =IF(G4<H4,"REORDER","OK") -> OK | M4: Duplicate Product IDs | N4: =IF(SUMPRODUCT(--(COUNTIF(InventoryTable[Product ID],InventoryTable[Product ID])>1))>0,"DUPLICATES FOUND","IDs unique") -> IDs unique
A5: P002 | B5: Keyboard | C5: Accessories | D5: 80 | E5: 30 | F5: 107 | G5: =D5 + E5 - F5 -> 3 | H5: 25 | I5: 899 | J5: =MAX(G5,0)*I5 -> 2697 | K5: =IF(G5<H5,"REORDER","OK") -> REORDER | M5: Missing Product Names | N5: =IF(COUNTBLANK(InventoryTable[Product Name])>0,"MISSING VALUES","Complete") -> Complete
A6: P003 | B6: USB-C Hub | C6: Accessories | D6: 55 | E6: 52 | F6: 77 | G6: =D6 + E6 - F6 -> 30 | H6: 18 | I6: 1499 | J6: =MAX(G6,0)*I6 -> 44970 | K6: =IF(G6<H6,"REORDER","OK") -> OK | M6: Negative Stock Check | N6: =IF(COUNTIF(InventoryTable[Current Stock],"<0")>0,"NEGATIVE STOCK","All Non-Negative") -> All Non-Negative
A7: P004 | B7: Laptop Stand | C7: Office Supplies | D7: 70 | E7: 30 | F7: 88 | G7: =D7 + E7 - F7 -> 12 | H7: 20 | I7: 1199 | J7: =MAX(G7,0)*I7 -> 14388 | K7: =IF(G7<H7,"REORDER","OK") -> REORDER | M7: Total SKUs Tracked | N7: =COUNTA(InventoryTable[Product ID]) -> 10
A8: P005 | B8: Webcam HD | C8: Electronics | D8: 40 | E8: 60 | F8: 97 | G8: =D8 + E8 - F8 -> 3 | H8: 15 | I8: 2499 | J8: =MAX(G8,0)*I8 -> 7497 | K8: =IF(G8<H8,"REORDER","OK") -> REORDER | M8: Total Current Units | N8: =SUM(InventoryTable[Current Stock]) -> 585
A9: P006 | B9: Headset | C9: Electronics | D9: 65 | E9: 62 | F9: 72 | G9: =D9 + E9 - F9 -> 55 | H9: 20 | I9: 1799 | J9: =MAX(G9,0)*I9 -> 98945 | K9: =IF(G9<H9,"REORDER","OK") -> OK | M9: Items Below Reorder | N9: =COUNTIF(InventoryTable[Reorder Alert],"REORDER") -> 4
A10: P007 | B10: Power Adapter | C10: Electronics | D10: 90 | E10: 2 | F10: 26 | G10: =D10 + E10 - F10 -> 66 | H10: 30 | I10: 999 | J10: =MAX(G10,0)*I10 -> 65934 | K10: =IF(G10<H10,"REORDER","OK") -> OK | M10: Total Inventory Value | N10: =SUM(InventoryTable[Inventory Value (₹)]) -> 384115
A11: P008 | B11: Notebook Pack | C11: Office Supplies | D11: 150 | E11: 37 | F11: 43 | G11: =D11 + E11 - F11 -> 144 | H11: 40 | I11: 249 | J11: =MAX(G11,0)*I11 -> 35856 | K11: =IF(G11<H11,"REORDER","OK") -> OK
A12: P009 | B12: Ethernet Cable | C12: Networking | D12: 200 | E12: 51 | F12: 103 | G12: =D12 + E12 - F12 -> 148 | H12: 60 | I12: 199 | J12: =MAX(G12,0)*I12 -> 29452 | K12: =IF(G12<H12,"REORDER","OK") -> OK
A13: P010 | B13: Portable SSD | C13: Storage | D13: 28 | E13: 31 | F13: 54 | G13: =D13 + E13 - F13 -> 5 | H13: 12 | I13: 4999 | J13: =MAX(G13,0)*I13 -> 24995 | K13: =IF(G13<H13,"REORDER","OK") -> REORDER

Sheet Employee Master
A1: Employee Master
A2: Employee directory, dynamic tenure calculation, VLOOKUP/XLOOKUP demonstrations, and ID integrity checks
A3: Employee ID | B3: Employee Name | C3: Department | D3: Designation | E3: Joining Date | F3: Tenure (Years) | G3: Employee Status | I3: Lookup Demonstration (VLOOKUP & XLOOKUP)
A4: E001 | B4: Aarav Sharma | C4: Operations | D4: MIS Executive | E4: 44970 | F4: =YEARFRAC(E4,TODAY()) -> 3.6833333 | G4: Active | I4: Lookup Employee ID (Input) | J4: E003
A5: E002 | B5: Diya Verma | C5: Field Operations | D5: Field Coordinator | E5: 44746 | F5: =YEARFRAC(E5,TODAY()) -> 4.2916667 | G5: Active | I5: VLOOKUP Employee Name | J5: =VLOOKUP(J4,EmployeeTable[[Employee ID]:[Employee Name]],2,FALSE()) -> Kabir Patel
A6: E003 | B6: Kabir Patel | C6: Warehouse | D6: Inventory Analyst | E6: 45306 | F6: =YEARFRAC(E6,TODAY()) -> 2.7611111 | G6: Active | I6: XLOOKUP Department | J6: =IFERROR(_xlfn.XLOOKUP(J4,EmployeeTable[Employee ID],EmployeeTable[Department],"Not found"),IFERROR(INDEX(EmployeeTable[Department],MATCH(J4,EmployeeTable[Employee ID],0)),"Not found")) -> Warehouse
A7: E004 | B7: Meera Singh | C7: Customer Service | D7: Operations Executive | E7: 44508 | F7: =YEARFRAC(E7,TODAY()) -> 4.9472222 | G7: Active | I7: XLOOKUP Designation | J7: =IFERROR(_xlfn.XLOOKUP(J4,EmployeeTable[Employee ID],EmployeeTable[Designation],"Not found"),IFERROR(INDEX(EmployeeTable[Designation],MATCH(J4,EmployeeTable[Employee ID],0)),"Not found")) -> Inventory Analyst
A8: E005 | B8: Ishaan Gupta | C8: Field Operations | D8: Field Executive | E8: 45159 | F8: =YEARFRAC(E8,TODAY()) -> 3.1611111 | G8: Active
A9: E006 | B9: Ananya Rao | C9: Operations | D9: MIS Analyst | E9: 44621 | F9: =YEARFRAC(E9,TODAY()) -> 4.6333333 | G9: Active | I9: Employee Data Quality Audit
A10: E007 | B10: Rohan Das | C10: Warehouse | D10: Store Executive | E10: 45418 | F10: =YEARFRAC(E10,TODAY()) -> 2.4527778 | G10: Active | I10: Duplicate ID Check | J10: =IF(SUMPRODUCT(--(COUNTIF(EmployeeTable[Employee ID],EmployeeTable[Employee ID])>1))>0,"DUPLICATE FOUND","IDs unique") -> IDs unique
A11: E008 | B11: Sana Khan | C11: Customer Service | D11: Order Coordinator | E11: 45201 | F11: =YEARFRAC(E11,TODAY()) -> 3.0472222 | G11: Active | I11: Missing Name Check | J11: =IF(COUNTBLANK(EmployeeTable[Employee Name])>0,"MISSING VALUES","Complete") -> Complete
A12: E009 | B12: Vivaan Joshi | C12: Field Operations | D12: Field Executive | E12: 43999 | F12: =YEARFRAC(E12,TODAY()) -> 6.3388889 | G12: Active
A13: E010 | B13: Ira Nair | C13: Operations | D13: Team Lead | E13: 43731 | F13: =YEARFRAC(E13,TODAY()) -> 7.0722222 | G13: Active

Sheet Daily MIS Report
A1: Daily MIS Report — Operational Snapshot
A2: Daily operational metrics • Set Period Start and Period End to the same day for a single-day view
A4: Period Start | B4: =TODAY() -> 46314 | D4: Edit yellow Period Start (B4) and Period End (B5) cells to recalculate all report metrics and charts for any custom reporting window.
A5: Period End | B5: =TODAY() -> 46314
E6: Inventory Exceptions Watchlist (Products Below Reorder Level)
A7: Operational Metric | B7: Period Result | C7: Domain | E7: Product ID | F7: Product Name | G7: Current Stock | H7: Reorder Level | I7: Alert Status
A8: Orders created | B8: =COUNTIFS(OrdersTable[Order Date],">="&$B$4,OrdersTable[Order Date],"<"&$B$5+1) -> 1 | C8: Orders | E8: ='Inventory Management'!A5 -> P002 | F8: ='Inventory Management'!B5 -> Keyboard | G8: ='Inventory Management'!G5 -> 3 | H8: ='Inventory Management'!H5 -> 25 | I8: ='Inventory Management'!K5 -> REORDER
A9: Delivered orders | B9: =COUNTIFS(OrdersTable[Actual Delivery],">="&$B$4,OrdersTable[Actual Delivery],"<"&$B$5+1) -> 2 | C9: Orders | E9: ='Inventory Management'!A7 -> P004 | F9: ='Inventory Management'!B7 -> Laptop Stand | G9: ='Inventory Management'!G7 -> 12 | H9: ='Inventory Management'!H7 -> 20 | I9: ='Inventory Management'!K7 -> REORDER
A10: Field activities assigned | B10: =COUNTIFS(FMSTable[Activity Date],">="&$B$4,FMSTable[Activity Date],"<"&$B$5+1) -> 2 | C10: Field Ops | E10: ='Inventory Management'!A8 -> P005 | F10: ='Inventory Management'!B8 -> Webcam HD | G10: ='Inventory Management'!G8 -> 3 | H10: ='Inventory Management'!H8 -> 15 | I10: ='Inventory Management'!K8 -> REORDER
A11: Field activities completed | B11: =COUNTIFS(FMSTable[Activity Date],">="&$B$4,FMSTable[Activity Date],"<"&$B$5+1,FMSTable[Status],"Completed") -> 2 | C11: Field Ops | E11: ='Inventory Management'!A13 -> P010 | F11: ='Inventory Management'!B13 -> Portable SSD | G11: ='Inventory Management'!G13 -> 5 | H11: ='Inventory Management'!H13 -> 12 | I11: ='Inventory Management'!K13 -> REORDER
A12: Checklist tasks due | B12: =COUNTIFS(ChecklistTable[Due Date],">="&$B$4,ChecklistTable[Due Date],"<"&$B$5+1) -> 1 | C12: Checklist
A13: On-time checklist completions | B13: =COUNTIFS(ChecklistTable[Completion Date],">="&$B$4,ChecklistTable[Completion Date],"<"&$B$5+1,ChecklistTable[Compliance Status],"On Time") -> 1 | C13: Checklist
A14: Low-stock products (Reorder) | B14: =COUNTIF(InventoryTable[Reorder Alert],"REORDER") -> 4 | C14: Inventory
A15: Order value (₹) | B15: =SUMIFS(OrdersTable[Order Value (₹)],OrdersTable[Order Date],">="&$B$4,OrdersTable[Order Date],"<"&$B$5+1) -> 2398 | C15: Revenue
A16: Current inventory value (₹) | B16: =SUM(InventoryTable[Inventory Value (₹)]) -> 384115 | C16: Inventory

Sheet Weekly MIS Report
A1: Weekly MIS Report — Monday to Sunday Operational Summary
A2: Weekly operational metrics • Defaults to Monday–Sunday of the current week; edit yellow cells for historical weeks
A4: Period Start | B4: =TODAY()-WEEKDAY(TODAY(),2)+1 -> 46314 | D4: Edit yellow Period Start (B4) and Period End (B5) cells to recalculate all report metrics and charts for any custom reporting window.
A5: Period End | B5: =TODAY()-WEEKDAY(TODAY(),2)+7 -> 46320
E6: Inventory Exceptions Watchlist (Products Below Reorder Level)
A7: Operational Metric | B7: Period Result | C7: Domain | E7: Product ID | F7: Product Name | G7: Current Stock | H7: Reorder Level | I7: Alert Status
A8: Orders created | B8: =COUNTIFS(OrdersTable[Order Date],">="&$B$4,OrdersTable[Order Date],"<"&$B$5+1) -> 1 | C8: Orders | E8: ='Inventory Management'!A5 -> P002 | F8: ='Inventory Management'!B5 -> Keyboard | G8: ='Inventory Management'!G5 -> 3 | H8: ='Inventory Management'!H5 -> 25 | I8: ='Inventory Management'!K5 -> REORDER
A9: Delivered orders | B9: =COUNTIFS(OrdersTable[Actual Delivery],">="&$B$4,OrdersTable[Actual Delivery],"<"&$B$5+1) -> 2 | C9: Orders | E9: ='Inventory Management'!A7 -> P004 | F9: ='Inventory Management'!B7 -> Laptop Stand | G9: ='Inventory Management'!G7 -> 12 | H9: ='Inventory Management'!H7 -> 20 | I9: ='Inventory Management'!K7 -> REORDER
A10: Field activities assigned | B10: =COUNTIFS(FMSTable[Activity Date],">="&$B$4,FMSTable[Activity Date],"<"&$B$5+1) -> 2 | C10: Field Ops | E10: ='Inventory Management'!A8 -> P005 | F10: ='Inventory Management'!B8 -> Webcam HD | G10: ='Inventory Management'!G8 -> 3 | H10: ='Inventory Management'!H8 -> 15 | I10: ='Inventory Management'!K8 -> REORDER
A11: Field activities completed | B11: =COUNTIFS(FMSTable[Activity Date],">="&$B$4,FMSTable[Activity Date],"<"&$B$5+1,FMSTable[Status],"Completed") -> 2 | C11: Field Ops | E11: ='Inventory Management'!A13 -> P010 | F11: ='Inventory Management'!B13 -> Portable SSD | G11: ='Inventory Management'!G13 -> 5 | H11: ='Inventory Management'!H13 -> 12 | I11: ='Inventory Management'!K13 -> REORDER
A12: Checklist tasks due | B12: =COUNTIFS(ChecklistTable[Due Date],">="&$B$4,ChecklistTable[Due Date],"<"&$B$5+1) -> 13 | C12: Checklist
A13: On-time checklist completions | B13: =COUNTIFS(ChecklistTable[Completion Date],">="&$B$4,ChecklistTable[Completion Date],"<"&$B$5+1,ChecklistTable[Compliance Status],"On Time") -> 2 | C13: Checklist
A14: Low-stock products (Reorder) | B14: =COUNTIF(InventoryTable[Reorder Alert],"REORDER") -> 4 | C14: Inventory
A15: Order value (₹) | B15: =SUMIFS(OrdersTable[Order Value (₹)],OrdersTable[Order Date],">="&$B$4,OrdersTable[Order Date],"<"&$B$5+1) -> 2398 | C15: Revenue
A16: Current inventory value (₹) | B16: =SUM(InventoryTable[Inventory Value (₹)]) -> 384115 | C16: Inventory

Sheet Monthly MIS Report
A1: Monthly MIS Report — Full Calendar Month Performance
A2: Monthly operational metrics • Defaults to the current calendar month; edit yellow cells for historical months
A4: Period Start | B4: =DATE(YEAR(TODAY()),MONTH(TODAY()),1) -> 46296 | D4: Edit yellow Period Start (B4) and Period End (B5) cells to recalculate all report metrics and charts for any custom reporting window.
A5: Period End | B5: =EOMONTH(TODAY(),0) -> 46326
E6: Inventory Exceptions Watchlist (Products Below Reorder Level)
A7: Operational Metric | B7: Period Result | C7: Domain | E7: Product ID | F7: Product Name | G7: Current Stock | H7: Reorder Level | I7: Alert Status
A8: Orders created | B8: =COUNTIFS(OrdersTable[Order Date],">="&$B$4,OrdersTable[Order Date],"<"&$B$5+1) -> 16 | C8: Orders | E8: ='Inventory Management'!A5 -> P002 | F8: ='Inventory Management'!B5 -> Keyboard | G8: ='Inventory Management'!G5 -> 3 | H8: ='Inventory Management'!H5 -> 25 | I8: ='Inventory Management'!K5 -> REORDER
A9: Delivered orders | B9: =COUNTIFS(OrdersTable[Actual Delivery],">="&$B$4,OrdersTable[Actual Delivery],"<"&$B$5+1) -> 11 | C9: Orders | E9: ='Inventory Management'!A7 -> P004 | F9: ='Inventory Management'!B7 -> Laptop Stand | G9: ='Inventory Management'!G7 -> 12 | H9: ='Inventory Management'!H7 -> 20 | I9: ='Inventory Management'!K7 -> REORDER
A10: Field activities assigned | B10: =COUNTIFS(FMSTable[Activity Date],">="&$B$4,FMSTable[Activity Date],"<"&$B$5+1) -> 19 | C10: Field Ops | E10: ='Inventory Management'!A8 -> P005 | F10: ='Inventory Management'!B8 -> Webcam HD | G10: ='Inventory Management'!G8 -> 3 | H10: ='Inventory Management'!H8 -> 15 | I10: ='Inventory Management'!K8 -> REORDER
A11: Field activities completed | B11: =COUNTIFS(FMSTable[Activity Date],">="&$B$4,FMSTable[Activity Date],"<"&$B$5+1,FMSTable[Status],"Completed") -> 13 | C11: Field Ops | E11: ='Inventory Management'!A13 -> P010 | F11: ='Inventory Management'!B13 -> Portable SSD | G11: ='Inventory Management'!G13 -> 5 | H11: ='Inventory Management'!H13 -> 12 | I11: ='Inventory Management'!K13 -> REORDER
A12: Checklist tasks due | B12: =COUNTIFS(ChecklistTable[Due Date],">="&$B$4,ChecklistTable[Due Date],"<"&$B$5+1) -> 35 | C12: Checklist
A13: On-time checklist completions | B13: =COUNTIFS(ChecklistTable[Completion Date],">="&$B$4,ChecklistTable[Completion Date],"<"&$B$5+1,ChecklistTable[Compliance Status],"On Time") -> 14 | C13: Checklist
A14: Low-stock products (Reorder) | B14: =COUNTIF(InventoryTable[Reorder Alert],"REORDER") -> 4 | C14: Inventory
A15: Order value (₹) | B15: =SUMIFS(OrdersTable[Order Value (₹)],OrdersTable[Order Date],">="&$B$4,OrdersTable[Order Date],"<"&$B$5+1) -> 116281 | C15: Revenue
A16: Current inventory value (₹) | B16: =SUM(InventoryTable[Inventory Value (₹)]) -> 384115 | C16: Inventory

Sheet Raw Data
A1: Raw Data — Operational Registers
A2: Left: FMS Field Activities (FMSTable) • Center: Checklist Compliance Register (ChecklistTable) • Right: Data Quality Audit
A3: FMS / Field Activities Register (FMSTable) | L3: Checklist Tasks Register (ChecklistTable) | W3: Data Quality Audit
A4: Activity ID | B4: Activity Date | C4: Employee ID | D4: Employee Name (XLOOKUP) | E4: Activity Type | F4: Assignment Date/Time | G4: Completion Date/Time | H4: Status | I4: TAT (Hours) | J4: SLA Result | L4: Task ID | M4: Employee ID | N4: Employee Name (XLOOKUP) | O4: Task Type | P4: Assigned Date | Q4: Due Date | R4: Completion Date | S4: Task Status | T4: Compliance Status | U4: On-Time Flag | W4: Check Metric | X4: Validation Result
A5: FMS0001 | B5: 46311 | C5: E004 | D5: =IFERROR(_xlfn.XLOOKUP(C5,EmployeeTable[Employee ID],EmployeeTable[Employee Name],"Not found"),IFERROR(INDEX(EmployeeTable[Employee Name],MATCH(C5,EmployeeTable[Employee ID],0)),"Not found")) -> Meera Singh | E5: Site Visit | F5: 46311.365 | G5: 46311.906 | H5: Completed | I5: =IF(G5="","",(G5-F5)*24) -> 13 | J5: =IF(H5="Completed",IF(I5<=4,"Within SLA","Delayed"),"") -> Delayed | L5: TASK0001 | M5: E008 | N5: =IFERROR(_xlfn.XLOOKUP(M5,EmployeeTable[Employee ID],EmployeeTable[Employee Name],"Not found"),IFERROR(INDEX(EmployeeTable[Employee Name],MATCH(M5,EmployeeTable[Employee ID],0)),"Not found")) -> Sana Khan | O5: Opening Checklist | P5: 46271 | Q5: 46272 | R5: 46274 | S5: Completed | T5: =IF(S5="Completed",IF(R5<=Q5,"On Time","Delayed"),IF(Q5<TODAY(),"Overdue","Pending")) -> Delayed | U5: =IF(S5="Completed",IF(R5<=Q5,1,0),0) -> 0 | W5: Duplicate Activity IDs | X5: =IF(SUMPRODUCT(--(COUNTIF(FMSTable[Activity ID],FMSTable[Activity ID])>1))>0,"DUPLICATES FOUND","IDs unique") -> IDs unique
A6: FMS0002 | B6: 46281 | C6: E007 | D6: =IFERROR(_xlfn.XLOOKUP(C6,EmployeeTable[Employee ID],EmployeeTable[Employee Name],"Not found"),IFERROR(INDEX(EmployeeTable[Employee Name],MATCH(C6,EmployeeTable[Employee ID],0)),"Not found")) -> Rohan Das | E6: Stock Audit | F6: 46281.417 | H6: Cancelled | I6: =IF(G6="","",(G6-F6)*24) | J6: =IF(H6="Completed",IF(I6<=4,"Within SLA","Delayed"),"") | L6: TASK0002 | M6: E005 | N6: =IFERROR(_xlfn.XLOOKUP(M6,EmployeeTable[Employee ID],EmployeeTable[Employee Name],"Not found"),IFERROR(INDEX(EmployeeTable[Employee Name],MATCH(M6,EmployeeTable[Employee ID],0)),"Not found")) -> Ishaan Gupta | O6: Safety Inspection | P6: 46304 | Q6: 46309 | R6: 46310 | S6: Completed | T6: =IF(S6="Completed",IF(R6<=Q6,"On Time","Delayed"),IF(Q6<TODAY(),"Overdue","Pending")) -> Delayed | U6: =IF(S6="Completed",IF(R6<=Q6,1,0),0) -> 0 | W6: Missing Activity IDs | X6: =IF(COUNTBLANK(FMSTable[Activity ID])>0,"MISSING VALUES","Complete") -> Complete
A7: FMS0003 | B7: 46309 | C7: E010 | D7: =IFERROR(_xlfn.XLOOKUP(C7,EmployeeTable[Employee ID],EmployeeTable[Employee Name],"Not found"),IFERROR(INDEX(EmployeeTable[Employee Name],MATCH(C7,EmployeeTable[Employee ID],0)),"Not found")) -> Ira Nair | E7: Customer Follow-up | F7: 46309.885 | G7: 46309.938 | H7: Completed | I7: =IF(G7="","",(G7-F7)*24) -> 1.25 | J7: =IF(H7="Completed",IF(I7<=4,"Within SLA","Delayed"),"") -> Within SLA | L7: TASK0003 | M7: E002 | N7: =IFERROR(_xlfn.XLOOKUP(M7,EmployeeTable[Employee ID],EmployeeTable[Employee Name],"Not found"),IFERROR(INDEX(EmployeeTable[Employee Name],MATCH(M7,EmployeeTable[Employee ID],0)),"Not found")) -> Diya Verma | O7: Stock Reconciliation | P7: 46272 | Q7: 46277 | R7: 46275 | S7: Completed | T7: =IF(S7="Completed",IF(R7<=Q7,"On Time","Delayed"),IF(Q7<TODAY(),"Overdue","Pending")) -> On Time | U7: =IF(S7="Completed",IF(R7<=Q7,1,0),0) -> 1 | W7: Duplicate Task IDs | X7: =IF(SUMPRODUCT(--(COUNTIF(ChecklistTable[Task ID],ChecklistTable[Task ID])>1))>0,"DUPLICATES FOUND","IDs unique") -> IDs unique
A8: FMS0004 | B8: 46271 | C8: E003 | D8: =IFERROR(_xlfn.XLOOKUP(C8,EmployeeTable[Employee ID],EmployeeTable[Employee Name],"Not found"),IFERROR(INDEX(EmployeeTable[Employee Name],MATCH(C8,EmployeeTable[Employee ID],0)),"Not found")) -> Kabir Patel | E8: Delivery Verification | F8: 46271.885 | G8: 46272.219 | H8: Completed | I8: =IF(G8="","",(G8-F8)*24) -> 8 | J8: =IF(H8="Completed",IF(I8<=4,"Within SLA","Delayed"),"") -> Delayed | L8: TASK0004 | M8: E009 | N8: =IFERROR(_xlfn.XLOOKUP(M8,EmployeeTable[Employee ID],EmployeeTable[Employee Name],"Not found"),IFERROR(INDEX(EmployeeTable[Employee Name],MATCH(M8,EmployeeTable[Employee ID],0)),"Not found")) -> Vivaan Joshi | O8: Customer Callback | P8: 46299 | Q8: 46304 | R8: 46303 | S8: Completed | T8: =IF(S8="Completed",IF(R8<=Q8,"On Time","Delayed"),IF(Q8<TODAY(),"Overdue","Pending")) -> On Time | U8: =IF(S8="Completed",IF(R8<=Q8,1,0),0) -> 1 | W8: Missing Task IDs | X8: =IF(COUNTBLANK(ChecklistTable[Task ID])>0,"MISSING VALUES","Complete") -> Complete
A9: FMS0005 | B9: 46299 | C9: E006 | D9: =IFERROR(_xlfn.XLOOKUP(C9,EmployeeTable[Employee ID],EmployeeTable[Employee Name],"Not found"),IFERROR(INDEX(EmployeeTable[Employee Name],MATCH(C9,EmployeeTable[Employee ID],0)),"Not found")) -> Ananya Rao | E9: Document Collection | F9: 46299.708 | G9: 46299.917 | H9: Completed | I9: =IF(G9="","",(G9-F9)*24) -> 5 | J9: =IF(H9="Completed",IF(I9<=4,"Within SLA","Delayed"),"") -> Delayed | L9: TASK0005 | M9: E006 | N9: =IFERROR(_xlfn.XLOOKUP(M9,EmployeeTable[Employee ID],EmployeeTable[Employee Name],"Not found"),IFERROR(INDEX(EmployeeTable[Employee Name],MATCH(M9,EmployeeTable[Employee ID],0)),"Not found")) -> Ananya Rao | O9: Document Review | P9: 46305 | Q9: 46305 | R9: 46305 | S9: Completed | T9: =IF(S9="Completed",IF(R9<=Q9,"On Time","Delayed"),IF(Q9<TODAY(),"Overdue","Pending")) -> On Time | U9: =IF(S9="Completed",IF(R9<=Q9,1,0),0) -> 1 | W9: Total FMS Records | X9: =COUNTA(FMSTable[Activity ID]) -> 50
A10: FMS0006 | B10: 46272 | C10: E009 | D10: =IFERROR(_xlfn.XLOOKUP(C10,EmployeeTable[Employee ID],EmployeeTable[Employee Name],"Not found"),IFERROR(INDEX(EmployeeTable[Employee Name],MATCH(C10,EmployeeTable[Employee ID],0)),"Not found")) -> Vivaan Joshi | E10: Quality Check | F10: 46272.729 | H10: In Progress | I10: =IF(G10="","",(G10-F10)*24) | J10: =IF(H10="Completed",IF(I10<=4,"Within SLA","Delayed"),"") | L10: TASK0006 | M10: E003 | N10: =IFERROR(_xlfn.XLOOKUP(M10,EmployeeTable[Employee ID],EmployeeTable[Employee Name],"Not found"),IFERROR(INDEX(EmployeeTable[Employee Name],MATCH(M10,EmployeeTable[Employee ID],0)),"Not found")) -> Kabir Patel | O10: End-of-Day Closure | P10: 46275 | Q10: 46275 | R10: 46277 | S10: Completed | T10: =IF(S10="Completed",IF(R10<=Q10,"On Time","Delayed"),IF(Q10<TODAY(),"Overdue","Pending")) -> Delayed | U10: =IF(S10="Completed",IF(R10<=Q10,1,0),0) -> 0 | W10: Total Checklist Tasks | X10: =COUNTA(ChecklistTable[Task ID]) -> 70
A11: FMS0007 | B11: 46301 | C11: E002 | D11: =IFERROR(_xlfn.XLOOKUP(C11,EmployeeTable[Employee ID],EmployeeTable[Employee Name],"Not found"),IFERROR(INDEX(EmployeeTable[Employee Name],MATCH(C11,EmployeeTable[Employee ID],0)),"Not found")) -> Diya Verma | E11: Site Visit | F11: 46301.771 | G11: 46301.979 | H11: Completed | I11: =IF(G11="","",(G11-F11)*24) -> 5 | J11: =IF(H11="Completed",IF(I11<=4,"Within SLA","Delayed"),"") -> Delayed | L11: TASK0007 | M11: E010 | N11: =IFERROR(_xlfn.XLOOKUP(M11,EmployeeTable[Employee ID],EmployeeTable[Employee Name],"Not found"),IFERROR(INDEX(EmployeeTable[Employee Name],MATCH(M11,EmployeeTable[Employee ID],0)),"Not found")) -> Ira Nair | O11: Opening Checklist | P11: 46311 | Q11: 46315 | S11: Pending | T11: =IF(S11="Completed",IF(R11<=Q11,"On Time","Delayed"),IF(Q11<TODAY(),"Overdue","Pending")) -> Pending | U11: =IF(S11="Completed",IF(R11<=Q11,1,0),0) -> 0
